<sdf version='1.7'>
  <model name='husky'>
    <link name='base_link'>
      <inertial>
        <pose>0.007303 -0.061985 0.167179 0 -0 0</pose>
        <mass>63.106</mass>
        <inertia>
          <ixx>3.96954</ixx>
          <ixy>-0.0553714</ixy>
          <ixz>-0.119685</ixz>
          <iyy>3.95272</iyy>
          <iyz>-0.413285</iyz>
          <izz>3.66157</izz>
        </inertia>
      </inertial>
      <collision name='base_link_fixed_joint_lump__base_collision1_collision'>
        <pose>0 0 0.061875 0 -0 0</pose>
        <geometry>
          <box>
            <size>0.9874 0.6909 0.12375</size>
          </box>
        </geometry>
      </collision>
      <collision name='base_link_fixed_joint_lump__base_collision2_collision_1'>
        <pose>0 0 0.175625 0 -0 0</pose>
        <geometry>
          <box>
            <size>0.78992 0.6909 0.10375</size>
          </box>
        </geometry>
      </collision>
      <collision name='base_link_fixed_joint_lump__front_bumper_collision_collision_2'>
        <pose>0.49 0 0.091 0 -0 0</pose>
        <geometry>
          <mesh>
            <scale>1 1 1</scale>
            <uri>model://husky_ur3_gazebo/meshes/bumper.dae</uri>
          </mesh>
        </geometry>
      </collision>
      <collision name='base_link_fixed_joint_lump__rear_bumper_collision_collision_3'>
        <pose>-0.49 0 0.091 0 -0 3.14159</pose>
        <geometry>
          <mesh>
            <scale>1 1 1</scale>
            <uri>model://husky_ur3_gazebo/meshes/bumper.dae</uri>
          </mesh>
        </geometry>
      </collision>
      <collision name='base_link_fixed_joint_lump__top_plate_link_collision_4'>
        <pose>0.0812 0 0.245 0 -0 0</pose>
        <geometry>
          <mesh>
            <scale>1 1 1</scale>
            <uri>model://husky_ur3_gazebo/meshes/top_plate.stl</uri>
          </mesh>
        </geometry>
      </collision>
      <collision name='base_link_fixed_joint_lump__control_box_ur3_link_collision_5'>
        <pose>-0.1138 0 0.478 1.57079 -0 0</pose>
        <geometry>
          <box>
            <size>0.28 0.46 0.37</size>
          </box>
        </geometry>
        <surface>
          <contact>
            <ode/>
          </contact>
          <friction>
            <ode/>
          </friction>
        </surface>
      </collision>
      <collision name='base_link_fixed_joint_lump__front_laser_base_link_collision_6'>
        <pose>0.4018 0 0.244365 3.14159 -0 0</pose>
        <geometry>
          <mesh>
            <scale>1 1 1</scale>
            <uri>model://husky_ur3_gazebo/meshes/sick_tim/sick_tim571.dae</uri>
          </mesh>
        </geometry>
      </collision>
      <collision name='base_link_fixed_joint_lump__h_camera_link_collision_7'>
        <pose>0.4918 0 0.3175 0 -0 0</pose>
        <geometry>
          <box>
            <size>0.02505 0.09 0.025</size>
          </box>
        </geometry>
        <surface>
          <contact>
            <ode/>
          </contact>
          <friction>
            <ode/>
          </friction>
        </surface>
      </collision>
      <collision name='base_link_fixed_joint_lump__ur3_base_link_collision_8'>
        <pose>0.3312 0 0.2515 0 0 -1.57</pose>
        <geometry>
          <mesh>
            <scale>1 1 1</scale>
            <uri>model://husky_ur3_gazebo/meshes/ur3/collision/base.stl</uri>
          </mesh>
        </geometry>
      </collision>
      <collision name='base_link_fixed_joint_lump__side_bumper_link_collision_9'>
        <pose>-0.0138 -0.36 0.478 1.5708 -1e-06 -1.57079</pose>
        <geometry>
          <box>
            <size>0.003 0.8 0.85</size>
          </box>
        </geometry>
      </collision>
      <collision name='base_link_fixed_joint_lump__side_bumper_link2_collision_10'>
        <pose>-0.0138 0.36 0.478 1.5708 -1e-06 -1.57079</pose>
        <geometry>
          <box>
            <size>0.003 0.8 0.85</size>
          </box>
        </geometry>
      </collision>
      <visual name='base_link_visual'>
        <pose>0 0 0 0 -0 0</pose>
        <geometry>
          <mesh>
            <scale>1 1 1</scale>
            <uri>model://husky_ur3_gazebo/meshes/base_link.dae</uri>
          </mesh>
        </geometry>
      </visual>
      <visual name='base_link_fixed_joint_lump__front_bumper_link_visual_1'>
        <pose>0.49 0 0.091 0 -0 0</pose>
        <geometry>
          <mesh>
            <scale>1 1 1</scale>
            <uri>model://husky_ur3_gazebo/meshes/bumper.dae</uri>
          </mesh>
        </geometry>
      </visual>
      <visual name='base_link_fixed_joint_lump__front_bumper_extension_link_visual_2'>
        <pose>0.49 0 0.091 0 -0 0</pose>
        <geometry>
          <mesh>
            <scale>1 1 1</scale>
            <uri>model://husky_ur3_gazebo/meshes/bumper_extension.dae</uri>
          </mesh>
        </geometry>
      </visual>
      <visual name='base_link_fixed_joint_lump__rear_bumper_link_visual_3'>
        <pose>-0.49 0 0.091 0 -0 3.14159</pose>
        <geometry>
          <mesh>
            <scale>1 1 1</scale>
            <uri>model://husky_ur3_gazebo/meshes/bumper.dae</uri>
          </mesh>
        </geometry>
      </visual>
      <visual name='base_link_fixed_joint_lump__rear_bumper_extension_link_visual_4'>
        <pose>-0.49 0 0.091 0 -0 3.14159</pose>
        <geometry>
          <mesh>
            <scale>1 1 1</scale>
            <uri>model://husky_ur3_gazebo/meshes/bumper_extension.dae</uri>
          </mesh>
        </geometry>
      </visual>
      <visual name='base_link_fixed_joint_lump__top_chassis_link_visual_5'>
        <pose>0 0 0 0 -0 0</pose>
        <geometry>
          <mesh>
            <scale>1 1 1</scale>
            <uri>model://husky_ur3_gazebo/meshes/top_chassis.dae</uri>
          </mesh>
        </geometry>
      </visual>
      <visual name='base_link_fixed_joint_lump__top_plate_link_visual_6'>
        <pose>0.0812 0 0.245 0 -0 0</pose>
        <geometry>
          <mesh>
            <scale>1 1 1</scale>
            <uri>model://husky_ur3_gazebo/meshes/top_plate.dae</uri>
          </mesh>
        </geometry>
      </visual>
      <visual name='base_link_fixed_joint_lump__control_box_ur3_link_visual_7'>
        <pose>-0.0138 0 0.478 1.5708 -1e-06 -1.57079</pose>
        <geometry>
          <mesh>
            <scale>0.001 0.001 0.001</scale>
            <uri>model://husky_ur3_gazebo/meshes/UR_Contorl_Box.stl</uri>
          </mesh>
        </geometry>
        <material>
          <script>
            <name>Gazebo/DarkGrey</name>
            <uri>file://media/materials/scripts/gazebo.material</uri>
          </script>
        </material>
      </visual>
      <visual name='base_link_fixed_joint_lump__front_laser_base_link_visual_8'>
        <pose>0.4018 0 0.244365 3.14159 -0 0</pose>
        <geometry>
          <mesh>
            <scale>1 1 1</scale>
            <uri>model://husky_ur3_gazebo/meshes/sick_tim/sick_tim571.dae</uri>
          </mesh>
        </geometry>
      </visual>
      <visual name='base_link_fixed_joint_lump__h_camera_link_visual_9'>
        <pose>0.4961 0 0.3175 1.5708 -0 1.5708</pose>
        <geometry>
          <mesh>
            <scale>1 1 1</scale>
            <uri>model://realsense2_description/meshes/d435.dae</uri>
          </mesh>
        </geometry>
      </visual>
      <visual name='base_link_fixed_joint_lump__ur3_base_link_visual_10'>
        <pose>0.3312 0 0.2515 0 0 -1.57</pose>
        <geometry>
          <mesh>
            <scale>1 1 1</scale>
            <uri>model://husky_ur3_gazebo/meshes/ur3/visual/base.dae</uri>
          </mesh>
        </geometry>
      </visual>
      <visual name='base_link_fixed_joint_lump__side_bumper_link_visual_11'>
        <pose>-0.0138 -0.36 0.478 1.5708 -1e-06 -1.57079</pose>
        <geometry>
          <box>
            <size>0.003 0.8 0.85</size>
          </box>
        </geometry>
      </visual>
      <visual name='base_link_fixed_joint_lump__side_bumper_link2_visual_12'>
        <pose>-0.0138 0.36 0.478 1.5708 -1e-06 -1.57079</pose>
        <geometry>
          <box>
            <size>0.003 0.8 0.85</size>
          </box>
        </geometry>
      </visual>
      <visual name='base_link_fixed_joint_lump__user_rail_link_visual_13'>
        <pose>0.272 0 0.245 0 -0 0</pose>
        <geometry>
          <mesh>
            <scale>1 1 1</scale>
            <uri>model://husky_ur3_gazebo/meshes/user_rail.dae</uri>
          </mesh>
        </geometry>
      </visual>
      <sensor name='base_contact_sensor3' type='contact'>
        <contact>
          <collision>base_link_fixed_joint_lump__base_collision1_collision</collision>
          <topic>__default_topic__</topic>
        </contact>
        <plugin name='my_plugin3' filename='libgazebo_ros_bumper.so'>
          <bumperTopicName>husky_collision</bumperTopicName>
          <frameName>base_link</frameName>
        </plugin>
      </sensor>
      <sensor name='base_contact_sensor4' type='contact'>
        <contact>
          <collision>base_link_fixed_joint_lump__base_collision2_collision_1</collision>
          <topic>__default_topic__</topic>
        </contact>
        <plugin name='my_plugin4' filename='libgazebo_ros_bumper.so'>
          <bumperTopicName>husky_collision</bumperTopicName>
          <frameName>base_link</frameName>
        </plugin>
      </sensor>
      <sensor name='base_contact_sensor' type='contact'>
        <contact>
          <collision>base_link_fixed_joint_lump__front_bumper_collision_collision_2</collision>
          <topic>__default_topic__</topic>
        </contact>
        <plugin name='my_plugin' filename='libgazebo_ros_bumper.so'>
          <bumperTopicName>husky_collision</bumperTopicName>
          <frameName>base_link</frameName>
        </plugin>
        <pose>0.49 0 0.091 0 -0 0</pose>
      </sensor>
      <sensor name='base_contact_sensor2' type='contact'>
        <contact>
          <collision>base_link_fixed_joint_lump__rear_bumper_collision_collision_3</collision>
          <topic>__default_topic__</topic>
        </contact>
        <plugin name='my_plugin2' filename='libgazebo_ros_bumper.so'>
          <bumperTopicName>husky_collision</bumperTopicName>
          <frameName>base_link</frameName>
        </plugin>
        <pose>-0.49 0 0.091 0 -0 3.14159</pose>
      </sensor>
      <sensor name='front_laser_sensor' type='ray'>
        <visualize>0</visualize>
        <update_rate>30</update_rate>
        <ray>
          <scan>
            <horizontal>
              <samples>542</samples>
              <resolution>1</resolution>
              <min_angle>-1.57</min_angle>
              <max_angle>1.57</max_angle>
            </horizontal>
          </scan>
          <range>
            <min>0.05</min>
            <max>25</max>
            <resolution>0.00575</resolution>
          </range>
          <noise>
            <type>gaussian</type>
            <mean>0</mean>
            <stddev>0.01</stddev>
          </noise>
        </ray>
        <plugin name='front_laser_controller' filename='libgazebo_ros_laser.so'>
          <topicName>scan</topicName>
          <frameName>/front_laser_link</frameName>
        </plugin>
        <pose>0.4018 0 0.181905 0 -0 0</pose>
      </sensor>
      <sensor name='h_camera' type='depth'>
        <always_on>1</always_on>
        <visualize>1</visualize>
        <camera>
          <horizontal_fov>1.0472</horizontal_fov>
          <image>
            <width>640</width>
            <height>480</height>
            <format>R8G8B8</format>
          </image>
          <depth_camera>
            <output>depths</output>
          </depth_camera>
          <clip>
            <near>0.11</near>
            <far>10</far>
          </clip>
        </camera>
        <plugin name='h_camera_controller' filename='libgazebo_ros_openni_kinect.so'>
          <alwaysOn>1</alwaysOn>
          <updateRate>20.0</updateRate>
          <cameraName>h_d435</cameraName>
          <frameName>h_camera_depth_optical_frame</frameName>
          <imageTopicName>rgb/h_image_raw</imageTopicName>
          <depthImageTopicName>depth/h_image_raw</depthImageTopicName>
          <pointCloudTopicName>depth/h_points</pointCloudTopicName>
          <cameraInfoTopicName>rgb/camera_info</cameraInfoTopicName>
          <depthImageCameraInfoTopicName>depth/camera_info</depthImageCameraInfoTopicName>
          <pointCloudCutoff>0.4</pointCloudCutoff>
          <hackBaseline>0.07</hackBaseline>
          <distortionK1>0.0</distortionK1>
          <distortionK2>0.0</distortionK2>
          <distortionK3>0.0</distortionK3>
          <distortionT1>0.0</distortionT1>
          <distortionT2>0.0</distortionT2>
          <CxPrime>0.0</CxPrime>
          <Cx>0.0</Cx>
          <Cy>0.0</Cy>
          <focalLength>0.0</focalLength>
        </plugin>
        <pose>0.4918 0.0175 0.3175 0 -0 0</pose>
      </sensor>
    </link>
    <joint name='front_left_wheel' type='revolute'>
      <pose relative_to='base_link'>0.256 0.2854 0.03282 0 -0 0</pose>
      <parent>base_link</parent>
      <child>front_left_wheel_link</child>
      <axis>
        <xyz>0 1 0</xyz>
        <limit>
          <lower>-1e+16</lower>
          <upper>1e+16</upper>
        </limit>
        <dynamics>
          <spring_reference>0</spring_reference>
          <spring_stiffness>0</spring_stiffness>
        </dynamics>
      </axis>
    </joint>
    <link name='front_left_wheel_link'>
      <pose relative_to='front_left_wheel'>0 0 0 0 -0 0</pose>
      <inertial>
        <pose>0 0 0 0 -0 0</pose>
        <mass>2.637</mass>
        <inertia>
          <ixx>0.02467</ixx>
          <ixy>0</ixy>
          <ixz>0</ixz>
          <iyy>0.04411</iyy>
          <iyz>0</iyz>
          <izz>0.02467</izz>
        </inertia>
      </inertial>
      <collision name='front_left_wheel_link_collision'>
        <pose>0 0 0 1.57079 -0 0</pose>
        <geometry>
          <cylinder>
            <length>0.1143</length>
            <radius>0.1651</radius>
          </cylinder>
        </geometry>
        <surface>
          <contact>
            <ode>
              <kp>1e+07</kp>
              <kd>1</kd>
            </ode>
          </contact>
          <friction>
            <ode>
              <mu>1</mu>
              <mu2>1</mu2>
              <fdir1>1 0 0</fdir1>
            </ode>
          </friction>
        </surface>
      </collision>
      <visual name='front_left_wheel_link_visual'>
        <pose>0 0 0 0 -0 0</pose>
        <geometry>
          <mesh>
            <scale>1 1 1</scale>
            <uri>model://husky_ur3_gazebo/meshes/wheel.dae</uri>
          </mesh>
        </geometry>
        <material>
          <script>
            <name>Gazebo/DarkGrey</name>
            <uri>file://media/materials/scripts/gazebo.material</uri>
          </script>
        </material>
      </visual>
      <self_collide>0</self_collide>
    </link>
    <joint name='front_right_wheel' type='revolute'>
      <pose relative_to='base_link'>0.256 -0.2854 0.03282 0 -0 0</pose>
      <parent>base_link</parent>
      <child>front_right_wheel_link</child>
      <axis>
        <xyz>0 1 0</xyz>
        <limit>
          <lower>-1e+16</lower>
          <upper>1e+16</upper>
        </limit>
        <dynamics>
          <spring_reference>0</spring_reference>
          <spring_stiffness>0</spring_stiffness>
        </dynamics>
      </axis>
    </joint>
    <link name='front_right_wheel_link'>
      <pose relative_to='front_right_wheel'>0 0 0 0 -0 0</pose>
      <inertial>
        <pose>0 0 0 0 -0 0</pose>
        <mass>2.637</mass>
        <inertia>
          <ixx>0.02467</ixx>
          <ixy>0</ixy>
          <ixz>0</ixz>
          <iyy>0.04411</iyy>
          <iyz>0</iyz>
          <izz>0.02467</izz>
        </inertia>
      </inertial>
      <collision name='front_right_wheel_link_collision'>
        <pose>0 0 0 1.57079 -0 0</pose>
        <geometry>
          <cylinder>
            <length>0.1143</length>
            <radius>0.1651</radius>
          </cylinder>
        </geometry>
        <surface>
          <contact>
            <ode>
              <kp>1e+07</kp>
              <kd>1</kd>
            </ode>
          </contact>
          <friction>
            <ode>
              <mu>1</mu>
              <mu2>1</mu2>
              <fdir1>1 0 0</fdir1>
            </ode>
          </friction>
        </surface>
      </collision>
      <visual name='front_right_wheel_link_visual'>
        <pose>0 0 0 0 -0 0</pose>
        <geometry>
          <mesh>
            <scale>1 1 1</scale>
            <uri>model://husky_ur3_gazebo/meshes/wheel.dae</uri>
          </mesh>
        </geometry>
        <material>
          <script>
            <name>Gazebo/DarkGrey</name>
            <uri>file://media/materials/scripts/gazebo.material</uri>
          </script>
        </material>
      </visual>
      <self_collide>0</self_collide>
    </link>
    <joint name='rear_left_wheel' type='revolute'>
      <pose relative_to='base_link'>-0.256 0.2854 0.03282 0 -0 0</pose>
      <parent>base_link</parent>
      <child>rear_left_wheel_link</child>
      <axis>
        <xyz>0 1 0</xyz>
        <limit>
          <lower>-1e+16</lower>
          <upper>1e+16</upper>
        </limit>
        <dynamics>
          <spring_reference>0</spring_reference>
          <spring_stiffness>0</spring_stiffness>
        </dynamics>
      </axis>
    </joint>
    <link name='rear_left_wheel_link'>
      <pose relative_to='rear_left_wheel'>0 0 0 0 -0 0</pose>
      <inertial>
        <pose>0 0 0 0 -0 0</pose>
        <mass>2.637</mass>
        <inertia>
          <ixx>0.02467</ixx>
          <ixy>0</ixy>
          <ixz>0</ixz>
          <iyy>0.04411</iyy>
          <iyz>0</iyz>
          <izz>0.02467</izz>
        </inertia>
      </inertial>
      <collision name='rear_left_wheel_link_collision'>
        <pose>0 0 0 1.57079 -0 0</pose>
        <geometry>
          <cylinder>
            <length>0.1143</length>
            <radius>0.1651</radius>
          </cylinder>
        </geometry>
        <surface>
          <contact>
            <ode>
              <kp>1e+07</kp>
              <kd>1</kd>
            </ode>
          </contact>
          <friction>
            <ode>
              <mu>0.05</mu>
              <mu2>0.05</mu2>
              <fdir1>1 0 0</fdir1>
            </ode>
          </friction>
        </surface>
      </collision>
      <visual name='rear_left_wheel_link_visual'>
        <pose>0 0 0 0 -0 0</pose>
        <geometry>
          <mesh>
            <scale>1 1 1</scale>
            <uri>model://husky_ur3_gazebo/meshes/wheel.dae</uri>
          </mesh>
        </geometry>
        <material>
          <script>
            <name>Gazebo/DarkGrey</name>
            <uri>file://media/materials/scripts/gazebo.material</uri>
          </script>
        </material>
      </visual>
      <self_collide>0</self_collide>
    </link>
    <joint name='rear_right_wheel' type='revolute'>
      <pose relative_to='base_link'>-0.256 -0.2854 0.03282 0 -0 0</pose>
      <parent>base_link</parent>
      <child>rear_right_wheel_link</child>
      <axis>
        <xyz>0 1 0</xyz>
        <limit>
          <lower>-1e+16</lower>
          <upper>1e+16</upper>
        </limit>
        <dynamics>
          <spring_reference>0</spring_reference>
          <spring_stiffness>0</spring_stiffness>
        </dynamics>
      </axis>
    </joint>
    <link name='rear_right_wheel_link'>
      <pose relative_to='rear_right_wheel'>0 0 0 0 -0 0</pose>
      <inertial>
        <pose>0 0 0 0 -0 0</pose>
        <mass>2.637</mass>
        <inertia>
          <ixx>0.02467</ixx>
          <ixy>0</ixy>
          <ixz>0</ixz>
          <iyy>0.04411</iyy>
          <iyz>0</iyz>
          <izz>0.02467</izz>
        </inertia>
      </inertial>
      <collision name='rear_right_wheel_link_collision'>
        <pose>0 0 0 1.57079 -0 0</pose>
        <geometry>
          <cylinder>
            <length>0.1143</length>
            <radius>0.1651</radius>
          </cylinder>
        </geometry>
        <surface>
          <contact>
            <ode>
              <kp>1e+07</kp>
              <kd>1</kd>
            </ode>
          </contact>
          <friction>
            <ode>
              <mu>0.05</mu>
              <mu2>0.05</mu2>
              <fdir1>1 0 0</fdir1>
            </ode>
          </friction>
        </surface>
      </collision>
      <visual name='rear_right_wheel_link_visual'>
        <pose>0 0 0 0 -0 0</pose>
        <geometry>
          <mesh>
            <scale>1 1 1</scale>
            <uri>model://husky_ur3_gazebo/meshes/wheel.dae</uri>
          </mesh>
        </geometry>
        <material>
          <script>
            <name>Gazebo/DarkGrey</name>
            <uri>file://media/materials/scripts/gazebo.material</uri>
          </script>
        </material>
      </visual>
      <self_collide>0</self_collide>
    </link>
    <joint name='shoulder_pan_joint' type='revolute'>
      <pose relative_to='base_link'>0.3312 0 0.4034 0 0 -1.57</pose>
      <parent>base_link</parent>
      <child>shoulder_link</child>
      <axis>
        <xyz>0 0 1</xyz>
        <limit>
          <lower>-3.14159</lower>
          <upper>3.14159</upper>
          <effort>330</effort>
          <velocity>2.16</velocity>
        </limit>
        <dynamics>
          <damping>0</damping>
          <friction>0</friction>
          <spring_reference>0</spring_reference>
          <spring_stiffness>0</spring_stiffness>
        </dynamics>
      </axis>
    </joint>
    <link name='shoulder_link'>
      <pose relative_to='shoulder_pan_joint'>0 0 0 0 -0 0</pose>
      <inertial>
        <pose>0 0 0 0 -0 0</pose>
        <mass>2</mass>
        <inertia>
          <ixx>0.00809316</ixx>
          <ixy>0</ixy>
          <ixz>0</ixz>
          <iyy>0.00809316</iyy>
          <iyz>0</iyz>
          <izz>0.005625</izz>
        </inertia>
      </inertial>
      <collision name='shoulder_link_collision'>
        <pose>0 0 0 0 -0 0</pose>
        <geometry>
          <mesh>
            <scale>1 1 1</scale>
            <uri>model://husky_ur3_gazebo/meshes/ur3/collision/shoulder.stl</uri>
          </mesh>
        </geometry>
        <surface>
          <contact>
            <ode/>
          </contact>
          <friction>
            <ode/>
          </friction>
        </surface>
      </collision>
      <visual name='shoulder_link_visual'>
        <pose>0 0 0 0 -0 0</pose>
        <geometry>
          <mesh>
            <scale>1 1 1</scale>
            <uri>model://husky_ur3_gazebo/meshes/ur3/visual/shoulder.dae</uri>
          </mesh>
        </geometry>
      </visual>
      <self_collide>1</self_collide>
    </link>
    <joint name='shoulder_lift_joint' type='revolute'>
      <pose relative_to='shoulder_link'>0 0.1198 0 0 1.5708 0</pose>
      <parent>shoulder_link</parent>
      <child>upper_arm_link</child>
      <axis>
        <xyz>0 1 0</xyz>
        <limit>
          <lower>-3.14159</lower>
          <upper>3.14159</upper>
          <effort>330</effort>
          <velocity>2.16</velocity>
        </limit>
        <dynamics>
          <damping>0</damping>
          <friction>0</friction>
          <spring_reference>0</spring_reference>
          <spring_stiffness>0</spring_stiffness>
        </dynamics>
      </axis>
    </joint>
    <link name='upper_arm_link'>
      <pose relative_to='shoulder_lift_joint'>0 0 0 0 -0 0</pose>
      <inertial>
        <pose>0 0 0.121825 0 -0 0</pose>
        <mass>3.42</mass>
        <inertia>
          <ixx>0.0217285</ixx>
          <ixy>0</ixy>
          <ixz>0</ixz>
          <iyy>0.0217285</iyy>
          <iyz>0</iyz>
          <izz>0.00961875</izz>
        </inertia>
      </inertial>
      <collision name='upper_arm_link_collision'>
        <pose>0 0 0 0 -0 0</pose>
        <geometry>
          <mesh>
            <scale>1 1 1</scale>
            <uri>model://husky_ur3_gazebo/meshes/ur3/collision/upperarm.stl</uri>
          </mesh>
        </geometry>
        <surface>
          <contact>
            <ode/>
          </contact>
          <friction>
            <ode/>
          </friction>
        </surface>
      </collision>
      <visual name='upper_arm_link_visual'>
        <pose>0 0 0 0 -0 0</pose>
        <geometry>
          <mesh>
            <scale>1 1 1</scale>
            <uri>model://husky_ur3_gazebo/meshes/ur3/visual/upperarm.dae</uri>
          </mesh>
        </geometry>
      </visual>
      <self_collide>1</self_collide>
    </link>
    <joint name='elbow_joint' type='revolute'>
      <pose relative_to='upper_arm_link'>0 -0.0925 0.24365 0 -0 0</pose>
      <parent>upper_arm_link</parent>
      <child>forearm_link</child>
      <axis>
        <xyz>0 1 0</xyz>
        <limit>
          <lower>-2.618</lower>
          <upper>3.14159</upper>
          <effort>150</effort>
          <velocity>3.15</velocity>
        </limit>
        <dynamics>
          <damping>0</damping>
          <friction>0</friction>
          <spring_reference>0</spring_reference>
          <spring_stiffness>0</spring_stiffness>
        </dynamics>
      </axis>
    </joint>
    <link name='forearm_link'>
      <pose relative_to='elbow_joint'>0 0 0 0 -0 0</pose>
      <inertial>
        <pose>0 0 0.106625 0 -0 0</pose>
        <mass>1.26</mass>
        <inertia>
          <ixx>0.00654681</ixx>
          <ixy>0</ixy>
          <ixz>0</ixz>
          <iyy>0.00654681</iyy>
          <iyz>0</iyz>
          <izz>0.00354375</izz>
        </inertia>
      </inertial>
      <collision name='forearm_link_collision'>
        <pose>0 0 0 0 -0 0</pose>
        <geometry>
          <mesh>
            <scale>1 1 1</scale>
            <uri>model://husky_ur3_gazebo/meshes/ur3/collision/forearm.stl</uri>
          </mesh>
        </geometry>
        <surface>
          <contact>
            <ode/>
          </contact>
          <friction>
            <ode/>
          </friction>
        </surface>
      </collision>
      <visual name='forearm_link_visual'>
        <pose>0 0 0 0 -0 0</pose>
        <geometry>
          <mesh>
            <scale>1 1 1</scale>
            <uri>model://husky_ur3_gazebo/meshes/ur3/visual/forearm.dae</uri>
          </mesh>
        </geometry>
      </visual>
      <self_collide>1</self_collide>
    </link>
    <joint name='wrist_1_joint' type='revolute'>
      <pose relative_to='forearm_link'>0 0 0.21325 0 1.5708 0</pose>
      <parent>forearm_link</parent>
      <child>wrist_1_link</child>
      <axis>
        <xyz>0 1 0</xyz>
        <limit>
          <lower>-3.14159</lower>
          <upper>3.14159</upper>
          <effort>54</effort>
          <velocity>3.2</velocity>
        </limit>
        <dynamics>
          <damping>0</damping>
          <friction>0</friction>
          <spring_reference>0</spring_reference>
          <spring_stiffness>0</spring_stiffness>
        </dynamics>
      </axis>
    </joint>
    <link name='wrist_1_link'>
      <pose relative_to='wrist_1_joint'>0 0 0 0 -0 0</pose>
      <inertial>
        <pose>0 0.08505 0 0 -0 0</pose>
        <mass>0.8</mass>
        <inertia>
          <ixx>0.002085</ixx>
          <ixy>0</ixy>
          <ixz>0</ixz>
          <iyy>0.002085</iyy>
          <iyz>0</iyz>
          <izz>0.00225</izz>
        </inertia>
      </inertial>
      <collision name='wrist_1_link_collision'>
        <pose>0 0 0 0 -0 0</pose>
        <geometry>
          <mesh>
            <scale>1 1 1</scale>
            <uri>model://husky_ur3_gazebo/meshes/ur3/collision/wrist1.stl</uri>
          </mesh>
        </geometry>
        <surface>
          <contact>
            <ode/>
          </contact>
          <friction>
            <ode/>
          </friction>
        </surface>
      </collision>
      <visual name='wrist_1_link_visual'>
        <pose>0 0 0 0 -0 0</pose>
        <geometry>
          <mesh>
            <scale>1 1 1</scale>
            <uri>model://husky_ur3_gazebo/meshes/ur3/visual/wrist1.dae</uri>
          </mesh>
        </geometry>
      </visual>
      <self_collide>1</self_collide>
    </link>
    <joint name='wrist_2_joint' type='revolute'>
      <pose relative_to='wrist_1_link'>0 0.08505 0 0 -0 0</pose>
      <parent>wrist_1_link</parent>
      <child>wrist_2_link</child>
      <axis>
        <xyz>0 0 1</xyz>
        <limit>
          <lower>-3.14159</lower>
          <upper>3.14159</upper>
          <effort>54</effort>
          <velocity>3.2</velocity>
        </limit>
        <dynamics>
          <damping>0</damping>
          <friction>0</friction>
          <spring_reference>0</spring_reference>
          <spring_stiffness>0</spring_stiffness>
        </dynamics>
      </axis>
    </joint>
    <link name='wrist_2_link'>
      <pose relative_to='wrist_2_joint'>0 0 0 0 -0 0</pose>
      <inertial>
        <pose>0 0 0.08535 0 -0 0</pose>
        <mass>0.8</mass>
        <inertia>
          <ixx>0.002085</ixx>
          <ixy>0</ixy>
          <ixz>0</ixz>
          <iyy>0.002085</iyy>
          <iyz>0</iyz>
          <izz>0.00225</izz>
        </inertia>
      </inertial>
      <collision name='wrist_2_link_collision'>
        <pose>0 0 0 0 -0 0</pose>
        <geometry>
          <mesh>
            <scale>1 1 1</scale>
            <uri>model://husky_ur3_gazebo/meshes/ur3/collision/wrist2.stl</uri>
          </mesh>
        </geometry>
        <surface>
          <contact>
            <ode/>
          </contact>
          <friction>
            <ode/>
          </friction>
        </surface>
      </collision>
      <visual name='wrist_2_link_visual'>
        <pose>0 0 0 0 -0 0</pose>
        <geometry>
          <mesh>
            <scale>1 1 1</scale>
            <uri>model://husky_ur3_gazebo/meshes/ur3/visual/wrist2.dae</uri>
          </mesh>
        </geometry>
      </visual>
      <self_collide>1</self_collide>
    </link>
    <joint name='wrist_3_joint' type='revolute'>
      <pose relative_to='wrist_2_link'>0 0 0.08535 0 -0 0</pose>
      <parent>wrist_2_link</parent>
      <child>wrist_3_link</child>
      <axis>
        <xyz>0 1 0</xyz>
        <limit>
          <lower>-3.14159</lower>
          <upper>3.14159</upper>
          <effort>54</effort>
          <velocity>3.2</velocity>
        </limit>
        <dynamics>
          <damping>0</damping>
          <friction>0</friction>
          <spring_reference>0</spring_reference>
          <spring_stiffness>0</spring_stiffness>
        </dynamics>
      </axis>
    </joint>
    <link name='wrist_3_link'>
      <pose relative_to='wrist_3_joint'>0 0 0 0 -0 0</pose>
      <inertial>
        <pose>0.001915 0.083899 -0.005745 1.5708 -0 0</pose>
        <mass>0.658</mass>
        <inertia>
          <ixx>1.0012</ixx>
          <ixy>5.89117e-05</ixy>
          <ixz>1.08375e-05</ixz>
          <iyy>1.00442</iyy>
          <iyz>-3.25126e-05</iyz>
          <izz>1.00426</izz>
        </inertia>
      </inertial>
      <collision name='wrist_3_link_collision'>
        <pose>0 0 0 0 -0 0</pose>
        <geometry>
          <mesh>
            <scale>1 1 1</scale>
            <uri>model://husky_ur3_gazebo/meshes/ur3/collision/wrist3.stl</uri>
          </mesh>
        </geometry>
        <surface>
          <contact>
            <ode/>
          </contact>
          <friction>
            <ode/>
          </friction>
        </surface>
      </collision>
      <collision name='wrist_3_link_fixed_joint_lump__ee_link_collision_1'>
        <pose>0 0.0719 0 0 -0 1.5708</pose>
        <geometry>
          <box>
            <size>0.01 0.01 0.01</size>
          </box>
        </geometry>
        <surface>
          <contact>
            <ode/>
          </contact>
          <friction>
            <ode/>
          </friction>
        </surface>
      </collision>
      <collision name='wrist_3_link_fixed_joint_lump__g_camera_link_collision_2'>
        <pose>0 0.0925 -0.0525 3.14159 -0 1.5708</pose>
        <geometry>
          <box>
            <size>0.02505 0.09 0.025</size>
          </box>
        </geometry>
        <surface>
          <contact>
            <ode/>
          </contact>
          <friction>
            <ode/>
          </friction>
        </surface>
      </collision>
      <collision name='wrist_3_link_fixed_joint_lump__rh_p12_rn_base_collision_3'>
        <pose>0 0.0819 0 -1.5708 1.5708 0</pose>
        <geometry>
          <mesh>
            <scale>0.001 0.001 0.001</scale>
            <uri>model://husky_ur3_gazebo/meshes/base.stl</uri>
          </mesh>
        </geometry>
        <surface>
          <contact>
            <ode>
              <max_vel>0</max_vel>
              <min_depth>0.001</min_depth>
            </ode>
          </contact>
          <friction>
            <ode>
              <mu>0.2</mu>
              <mu2>0.2</mu2>
            </ode>
          </friction>
        </surface>
      </collision>
      <visual name='wrist_3_link_visual'>
        <pose>0 0 0 0 -0 0</pose>
        <geometry>
          <mesh>
            <scale>1 1 1</scale>
            <uri>model://husky_ur3_gazebo/meshes/ur3/visual/wrist3.dae</uri>
          </mesh>
        </geometry>
      </visual>
      <visual name='wrist_3_link_fixed_joint_lump__g_camera_link_visual_1'>
        <pose>0 0.0968 -0.0525 -1.5708 -0 0</pose>
        <geometry>
          <mesh>
            <scale>1 1 1</scale>
            <uri>model://realsense2_description/meshes/d435.dae</uri>
          </mesh>
        </geometry>
      </visual>
      <visual name='wrist_3_link_fixed_joint_lump__rh_p12_rn_base_visual_2'>
        <pose>0 0.0819 0 -1.5708 1.5708 0</pose>
        <geometry>
          <mesh>
            <scale>0.001 0.001 0.001</scale>
            <uri>model://husky_ur3_gazebo/meshes/base.stl</uri>
          </mesh>
        </geometry>
        <material>
          <script>
            <name>Gazebo/DarkGrey</name>
            <uri>file://media/materials/scripts/gazebo.material</uri>
          </script>
        </material>
      </visual>
      <self_collide>1</self_collide>
      <sensor name='g_camera' type='depth'>
        <always_on>1</always_on>
        <visualize>1</visualize>
        <camera>
          <horizontal_fov>1.0472</horizontal_fov>
          <image>
            <width>640</width>
            <height>480</height>
            <format>R8G8B8</format>
          </image>
          <depth_camera>
            <output>depths</output>
          </depth_camera>
          <clip>
            <near>0.11</near>
            <far>10</far>
          </clip>
        </camera>
        <plugin name='g_camera_controller' filename='libgazebo_ros_openni_kinect.so'>
          <alwaysOn>1</alwaysOn>
          <updateRate>20.0</updateRate>
          <cameraName>g_d435</cameraName>
          <frameName>g_camera_depth_optical_frame</frameName>
          <imageTopicName>rgb/g_image_raw</imageTopicName>
          <depthImageTopicName>depth/g_image_raw</depthImageTopicName>
          <pointCloudTopicName>depth/g_points</pointCloudTopicName>
          <cameraInfoTopicName>rgb/camera_info</cameraInfoTopicName>
          <depthImageCameraInfoTopicName>depth/camera_info</depthImageCameraInfoTopicName>
          <pointCloudCutoff>0.4</pointCloudCutoff>
          <hackBaseline>0.07</hackBaseline>
          <distortionK1>0.0</distortionK1>
          <distortionK2>0.0</distortionK2>
          <distortionK3>0.0</distortionK3>
          <distortionT1>0.0</distortionT1>
          <distortionT2>0.0</distortionT2>
          <CxPrime>0.0</CxPrime>
          <Cx>0.0</Cx>
          <Cy>0.0</Cy>
          <focalLength>0.0</focalLength>
        </plugin>
        <pose>0.0175 0.0925 -0.0525 3.14159 -0 1.5708</pose>
      </sensor>
    </link>
    <joint name='rh_l1' type='revolute'>
      <pose relative_to='wrist_3_link'>0.008 0.1299 3.8e-05 -0 1.57 1.5708</pose>
      <parent>wrist_3_link</parent>
      <child>rh_p12_rn_l1</child>
      <axis>
        <xyz>-1 0 0</xyz>
        <limit>
          <lower>0</lower>
          <upper>1.1</upper>
          <effort>1000</effort>
          <velocity>6.5</velocity>
        </limit>
        <dynamics>
          <damping>0.7</damping>
          <friction>0</friction>
          <spring_reference>0</spring_reference>
          <spring_stiffness>0</spring_stiffness>
        </dynamics>
      </axis>
    </joint>
    <link name='rh_p12_rn_l1'>
      <pose relative_to='rh_l1'>0 0 0 0 -0 0</pose>
      <inertial>
        <pose>0 -0.034 0.004 0 -0 0</pose>
        <mass>0.068</mass>
        <inertia>
          <ixx>1</ixx>
          <ixy>0</ixy>
          <ixz>0</ixz>
          <iyy>1</iyy>
          <iyz>0</iyz>
          <izz>1</izz>
        </inertia>
      </inertial>
      <collision name='rh_p12_rn_l1_collision'>
        <pose>0 0 0 0 -0 0</pose>
        <geometry>
          <mesh>
            <scale>0.001 0.001 0.001</scale>
            <uri>model://husky_ur3_gazebo/meshes/l1.stl</uri>
          </mesh>
        </geometry>
        <surface>
          <contact>
            <ode>
              <max_vel>0</max_vel>
              <min_depth>0.001</min_depth>
            </ode>
          </contact>
          <friction>
            <ode>
              <mu>15</mu>
              <mu2>150</mu2>
            </ode>
          </friction>
        </surface>
      </collision>
      <visual name='rh_p12_rn_l1_visual'>
        <pose>0 0 0 0 -0 0</pose>
        <geometry>
          <mesh>
            <scale>0.001 0.001 0.001</scale>
            <uri>model://husky_ur3_gazebo/meshes/l1.stl</uri>
          </mesh>
        </geometry>
        <material>
          <script>
            <name>Gazebo/DarkGrey</name>
            <uri>file://media/materials/scripts/gazebo.material</uri>
          </script>
        </material>
      </visual>
    </link>
    <joint name='rh_l2' type='revolute'>
      <pose relative_to='rh_p12_rn_l1'>0 -0.049363 0.0285 0 -0 0</pose>
      <parent>rh_p12_rn_l1</parent>
      <child>rh_p12_rn_l2</child>
      <axis>
        <xyz>1 0 0</xyz>
        <limit>
          <lower>0</lower>
          <upper>1</upper>
          <effort>1000</effort>
          <velocity>6.5</velocity>
        </limit>
        <dynamics>
          <damping>0.7</damping>
          <friction>0</friction>
          <spring_reference>0</spring_reference>
          <spring_stiffness>0</spring_stiffness>
        </dynamics>
      </axis>
    </joint>
    <link name='rh_p12_rn_l2'>
      <pose relative_to='rh_l2'>0 0 0 0 -0 0</pose>
      <inertial>
        <pose>0 -0.006 0.011 0 -0 0</pose>
        <mass>0.022</mass>
        <inertia>
          <ixx>1</ixx>
          <ixy>0</ixy>
          <ixz>0</ixz>
          <iyy>1</iyy>
          <iyz>0</iyz>
          <izz>1</izz>
        </inertia>
      </inertial>
      <collision name='rh_p12_rn_l2_collision'>
        <pose>0 0 0 0 -0 0</pose>
        <geometry>
          <mesh>
            <scale>0.001 0.001 0.001</scale>
            <uri>model://husky_ur3_gazebo/meshes/l2.stl</uri>
          </mesh>
        </geometry>
        <surface>
          <contact>
            <ode>
              <max_vel>0</max_vel>
              <min_depth>0.001</min_depth>
            </ode>
          </contact>
          <friction>
            <ode>
              <mu>15</mu>
              <mu2>150</mu2>
            </ode>
          </friction>
        </surface>
      </collision>
      <visual name='rh_p12_rn_l2_visual'>
        <pose>0 0 0 0 -0 0</pose>
        <geometry>
          <mesh>
            <scale>0.001 0.001 0.001</scale>
            <uri>model://husky_ur3_gazebo/meshes/l2.stl</uri>
          </mesh>
        </geometry>
        <material>
          <script>
            <name>Gazebo/DarkGrey</name>
            <uri>file://media/materials/scripts/gazebo.material</uri>
          </script>
        </material>
      </visual>
    </link>
    <joint name='rh_p12_rn' type='revolute'>
      <pose relative_to='wrist_3_link'>-0.008 0.1299 3.8e-05 -0 1.57 1.5708</pose>
      <parent>wrist_3_link</parent>
      <child>rh_p12_rn_r1</child>
      <axis>
        <xyz>1 0 0</xyz>
        <limit>
          <lower>0</lower>
          <upper>1.1</upper>
          <effort>1000</effort>
          <velocity>6.5</velocity>
        </limit>
        <dynamics>
          <damping>0.7</damping>
          <friction>0</friction>
          <spring_reference>0</spring_reference>
          <spring_stiffness>0</spring_stiffness>
        </dynamics>
      </axis>
    </joint>
    <link name='rh_p12_rn_r1'>
      <pose relative_to='rh_p12_rn'>0 0 0 0 -0 0</pose>
      <inertial>
        <pose>0 0.034 0.004 0 -0 0</pose>
        <mass>0.068</mass>
        <inertia>
          <ixx>1</ixx>
          <ixy>0</ixy>
          <ixz>0</ixz>
          <iyy>1</iyy>
          <iyz>0</iyz>
          <izz>1</izz>
        </inertia>
      </inertial>
      <collision name='rh_p12_rn_r1_collision'>
        <pose>0 0 0 0 -0 0</pose>
        <geometry>
          <mesh>
            <scale>0.001 0.001 0.001</scale>
            <uri>model://husky_ur3_gazebo/meshes/r1.stl</uri>
          </mesh>
        </geometry>
        <surface>
          <contact>
            <ode>
              <max_vel>0</max_vel>
              <min_depth>0.001</min_depth>
            </ode>
          </contact>
          <friction>
            <ode>
              <mu>15</mu>
              <mu2>150</mu2>
            </ode>
          </friction>
        </surface>
      </collision>
      <visual name='rh_p12_rn_r1_visual'>
        <pose>0 0 0 0 -0 0</pose>
        <geometry>
          <mesh>
            <scale>0.001 0.001 0.001</scale>
            <uri>model://husky_ur3_gazebo/meshes/r1.stl</uri>
          </mesh>
        </geometry>
        <material>
          <script>
            <name>Gazebo/DarkGrey</name>
            <uri>file://media/materials/scripts/gazebo.material</uri>
          </script>
        </material>
      </visual>
    </link>
    <joint name='rh_r2' type='revolute'>
      <pose relative_to='rh_p12_rn_r1'>0 0.049363 0.0285 0 -0 0</pose>
      <parent>rh_p12_rn_r1</parent>
      <child>rh_p12_rn_r2</child>
      <axis>
        <xyz>-1 0 0</xyz>
        <limit>
          <lower>0</lower>
          <upper>1</upper>
          <effort>1000</effort>
          <velocity>6.5</velocity>
        </limit>
        <dynamics>
          <damping>0.7</damping>
          <friction>0</friction>
          <spring_reference>0</spring_reference>
          <spring_stiffness>0</spring_stiffness>
        </dynamics>
      </axis>
    </joint>
    <link name='rh_p12_rn_r2'>
      <pose relative_to='rh_r2'>0 0 0 0 -0 0</pose>
      <inertial>
        <pose>0 0.006 0.011 0 -0 0</pose>
        <mass>0.022</mass>
        <inertia>
          <ixx>1</ixx>
          <ixy>0</ixy>
          <ixz>0</ixz>
          <iyy>1</iyy>
          <iyz>0</iyz>
          <izz>1</izz>
        </inertia>
      </inertial>
      <collision name='rh_p12_rn_r2_collision'>
        <pose>0 0 0 0 -0 0</pose>
        <geometry>
          <mesh>
            <scale>0.001 0.001 0.001</scale>
            <uri>model://husky_ur3_gazebo/meshes/r2.stl</uri>
          </mesh>
        </geometry>
        <surface>
          <contact>
            <ode>
              <max_vel>0</max_vel>
              <min_depth>0.001</min_depth>
            </ode>
          </contact>
          <friction>
            <ode>
              <mu>15</mu>
              <mu2>150</mu2>
            </ode>
          </friction>
        </surface>
      </collision>
      <visual name='rh_p12_rn_r2_visual'>
        <pose>0 0 0 0 -0 0</pose>
        <geometry>
          <mesh>
            <scale>0.001 0.001 0.001</scale>
            <uri>model://husky_ur3_gazebo/meshes/r2.stl</uri>
          </mesh>
        </geometry>
        <material>
          <script>
            <name>Gazebo/DarkGrey</name>
            <uri>file://media/materials/scripts/gazebo.material</uri>
          </script>
        </material>
      </visual>
    </link>
    <plugin name='gazebo_ros_control' filename='libgazebo_ros_control.so'>
      <robotNamespace>/husky</robotNamespace>
    </plugin>
    <plugin name='imu_controller' filename='libhector_gazebo_ros_imu.so'>
      <robotNamespace>/husky</robotNamespace>
      <updateRate>50.0</updateRate>
      <bodyName>base_link</bodyName>
      <topicName>imu/data</topicName>
      <accelDrift>0.005 0.005 0.005</accelDrift>
      <accelGaussianNoise>0.005 0.005 0.005</accelGaussianNoise>
      <rateDrift>0.005 0.005 0.005</rateDrift>
      <rateGaussianNoise>0.005 0.005 0.005</rateGaussianNoise>
      <headingDrift>0.005</headingDrift>
      <headingGaussianNoise>0.005</headingGaussianNoise>
    </plugin>
    <plugin name='gps_controller' filename='libhector_gazebo_ros_gps.so'>
      <robotNamespace>/husky</robotNamespace>
      <updateRate>40</updateRate>
      <bodyName>base_link</bodyName>
      <frameId>base_link</frameId>
      <topicName>navsat/fix</topicName>
      <velocityTopicName>navsat/vel</velocityTopicName>
      <referenceLatitude>49.9</referenceLatitude>
      <referenceLongitude>8.9</referenceLongitude>
      <referenceHeading>0</referenceHeading>
      <referenceAltitude>0</referenceAltitude>
      <drift>0.0001 0.0001 0.0001</drift>
    </plugin>
    <static>0</static>
    <plugin name='p3d_base_controller' filename='libgazebo_ros_p3d.so'>
      <alwaysOn>1</alwaysOn>
      <updateRate>50.0</updateRate>
      <topicName>base_pose_ground_truth</topicName>
      <gaussianNoise>0.01</gaussianNoise>
      <frameName>map</frameName>
      <xyzOffsets>0 0 0</xyzOffsets>
      <rpyOffsets>0 0 0</rpyOffsets>
      <bodyName>base_link</bodyName>
      <xyzOffset>0 0 -0.13228</xyzOffset>
      <rpyOffset>0 -0 0</rpyOffset>
      <ignition::corrected_offsets>1</ignition::corrected_offsets>
    </plugin>
  </model>
</sdf>
